#VRML_SIM R2021a utf8
# license: Copyright Cyberbotics Ltd. Licensed for use only with Webots.
# license url: https://cyberbotics.com/webots_assets_license
# tags: static
# documentation url: https://www.cyberbotics.com/doc/guide/surveyor
# Thymio II mobile robot.

PROTO Thymio2_enu [
  field SFVec3f    translation     0 0 0           # Is `Transform.translation`.
  field SFRotation rotation        1 0 0 0         # Is `Transform.rotation`.
  field SFString   name            "Thymio II"     # Is `Solid.name`.
  field SFString   controller      "thymio2_aseba" # Is `Robot.controller`.
  field MFString   controllerArgs  "port=33333"    # Is `Robot.controllerArgs`.
  field SFString   customData      ""              # Is `Robot.customData`.
  field SFBool     supervisor      FALSE           # Is `Robot.supervisor`.
  field SFBool     synchronization TRUE            # Is `Robot.synchronization`.
  field SFString   window          ""              # Is `Robot.window`.
  field SFString   contactMaterial "thymio body"   # Defines the `Solid.contactMaterial` for the body.
]
{
  Robot {
    translation IS translation
    rotation IS rotation
    controller IS controller
    controllerArgs IS controllerArgs
    customData IS customData
    supervisor IS supervisor
    synchronization IS synchronization
    name IS name
    window IS window
    model "Thymio II"
    children [
      Transform {
        translation -0.130000 0.000000 0.08000
        rotation 0.000000 0.000000 1.0 1.5708
        scale 0.001 0.001 0.001
        children[
              Shape {
                appearance DEF DarkGreen PBRAppearance {
                  baseColor 0.0 0.0 0.0
                  transparency 0.000000
                  roughness 0.000
                  metalness 1.0
                  emissiveColor 0.0 0.0 0.0
                }
                geometry Mesh {
                  url ["/home/unicorn/foxy_ws/src/unicorn_description/urdf/am_chassis.stl"]
                }
              }
            ]
      }
      Transform {
        rotation 1 0 0 1.5708
        children [
              Transform {
        rotation 0 1 0 1.5708
        children [
      Transform {
        children [
          Shape {
            appearance DEF MAIN_APPEARANCE PBRAppearance {
              baseColor 1 1 1
              roughness 0.1
              metalness 0
            }
            geometry Thymio2MainIndexedFaceSet {
            }
          }
          Shape {
            appearance PBRAppearance {
              baseColor 0.1 0.1 0.1
              roughness 0.2
              metalness 0
            }
            geometry Thymio2SecondaryIndexedFaceSet {
            }
          }
        ]
      }
      HingeJoint {
        jointParameters HingeJointParameters {
          anchor -0.05 0.021 0
        }
        device [
          RotationalMotor {
            name "motor.right"
            maxVelocity 9.53
          }
          PositionSensor {
            name "motor.right.position"
          }
        ]
        endPoint Solid {
          translation -0.05 0.021 0
          rotation 1 0 0 0
          children [
            DEF WHEEL_SHAPE Shape {
              appearance DEF WHITE_PLASTIC_APPEARANCE PBRAppearance {
                baseColor 0.9 0.9 0.9
                roughness 0.1
                metalness 0
              }
              geometry Thymio2WheelIndexedFaceSet {
              }
            }
            DEF TIRE_SHAPE Shape {
              appearance PBRAppearance {
                baseColor 0.1 0.1 0.1
                metalness 0
                roughness 0.3
              }
              geometry Thymio2TireIndexedFaceSet {
              }
            }
          ]
          name "right wheel"
          boundingObject Transform {
            rotation 0 0 1 1.5708
            children [
              DEF WHEEL_BO_SHAPE Shape {
                geometry Cylinder {
                  height 0.015
                  radius 0.021
                }
              }
            ]
          }
          physics Physics {
            density -1
            mass 0.024
          }
        }
      }
      HingeJoint {
        jointParameters HingeJointParameters {
          anchor 0.05 0.021 0
        }
        device [
          RotationalMotor {
            name "motor.left"
            maxVelocity 9.53
          }
          PositionSensor {
            name "motor.left.position"
          }
        ]
        endPoint Solid {
          translation 0.05 0.021 0
          rotation 1 0 0 0
          children [
            Transform {
              rotation 0 1 0 3.14159
              children [
                USE WHEEL_SHAPE
                USE TIRE_SHAPE
              ]
            }
          ]
          name "left wheel"
          boundingObject Transform {
            rotation 0 0 1 1.5708
            children [
              DEF WHEEL_BO_SHAPE Shape {
                geometry Cylinder {
                  height 0.015
                  radius 0.021
                }
              }
            ]
          }
          physics Physics {
            density -1
            mass 0.024
          }
        }
      }
      ]
      }
      ]
      }
    ]
    contactMaterial IS contactMaterial
    boundingObject Group {
      children [
        Transform {
          translation 0.03 0 0.03
          children [
            Shape {
              geometry Box {
                size 0.1 0.08 0.05
              }
            }
          ]
        }
        Transform {
          translation 0.06 0 0.0065
            children [
              Shape {
                geometry Sphere {
                  radius 0.008
                }
              }
            ]
         }
      ]
    }
    physics Physics {
      density -1
      mass 0.08
    }
  }
}
